[2023-01-30T17:17:20.944+0000] {taskinstance.py:1083} INFO - Dependencies all met for <TaskInstance: crawl_data.save-to-hdfs scheduled__2023-01-30T16:05:00+00:00 [queued]>
[2023-01-30T17:17:20.954+0000] {taskinstance.py:1083} INFO - Dependencies all met for <TaskInstance: crawl_data.save-to-hdfs scheduled__2023-01-30T16:05:00+00:00 [queued]>
[2023-01-30T17:17:20.954+0000] {taskinstance.py:1279} INFO - 
--------------------------------------------------------------------------------
[2023-01-30T17:17:20.954+0000] {taskinstance.py:1280} INFO - Starting attempt 3 of 4
[2023-01-30T17:17:20.954+0000] {taskinstance.py:1281} INFO - 
--------------------------------------------------------------------------------
[2023-01-30T17:17:20.970+0000] {taskinstance.py:1300} INFO - Executing <Task(SSHOperator): save-to-hdfs> on 2023-01-30 16:05:00+00:00
[2023-01-30T17:17:20.974+0000] {standard_task_runner.py:55} INFO - Started process 16756 to run task
[2023-01-30T17:17:20.977+0000] {standard_task_runner.py:82} INFO - Running: ['***', 'tasks', 'run', 'crawl_data', 'save-to-hdfs', 'scheduled__2023-01-30T16:05:00+00:00', '--job-id', '1939', '--raw', '--subdir', 'DAGS_FOLDER/crawl_data.py', '--cfg-path', '/tmp/tmp4648_p_y']
[2023-01-30T17:17:20.977+0000] {standard_task_runner.py:83} INFO - Job 1939: Subtask save-to-hdfs
[2023-01-30T17:17:21.035+0000] {task_command.py:388} INFO - Running <TaskInstance: crawl_data.save-to-hdfs scheduled__2023-01-30T16:05:00+00:00 [running]> on host 9be4ecca8506
[2023-01-30T17:17:21.104+0000] {taskinstance.py:1509} INFO - Exporting the following env vars:
AIRFLOW_CTX_DAG_OWNER=phukaioh
AIRFLOW_CTX_DAG_ID=crawl_data
AIRFLOW_CTX_TASK_ID=save-to-hdfs
AIRFLOW_CTX_EXECUTION_DATE=2023-01-30T16:05:00+00:00
AIRFLOW_CTX_TRY_NUMBER=3
AIRFLOW_CTX_DAG_RUN_ID=scheduled__2023-01-30T16:05:00+00:00
[2023-01-30T17:17:21.105+0000] {ssh.py:133} INFO - Creating ssh_client
[2023-01-30T17:17:21.105+0000] {ssh.py:283} WARNING - No Host Key Verification. This won't protect against Man-In-The-Middle attacks
[2023-01-30T17:17:31.113+0000] {ssh.py:325} INFO - Failed to connect. Sleeping before retry attempt 1
[2023-01-30T17:17:44.781+0000] {ssh.py:325} INFO - Failed to connect. Sleeping before retry attempt 2
[2023-01-30T17:17:58.749+0000] {taskinstance.py:1768} ERROR - Task failed with exception
Traceback (most recent call last):
  File "/home/airflow/.local/lib/python3.7/site-packages/airflow/providers/ssh/operators/ssh.py", line 170, in execute
    with self.get_ssh_client() as ssh_client:
  File "/home/airflow/.local/lib/python3.7/site-packages/airflow/providers/ssh/operators/ssh.py", line 134, in get_ssh_client
    return self.get_hook().get_conn()
  File "/home/airflow/.local/lib/python3.7/site-packages/airflow/providers/ssh/hooks/ssh.py", line 332, in get_conn
    before_sleep=log_before_sleep,
  File "/home/airflow/.local/lib/python3.7/site-packages/tenacity/__init__.py", line 384, in __iter__
    do = self.iter(retry_state=retry_state)
  File "/home/airflow/.local/lib/python3.7/site-packages/tenacity/__init__.py", line 362, in iter
    raise retry_exc.reraise()
  File "/home/airflow/.local/lib/python3.7/site-packages/tenacity/__init__.py", line 195, in reraise
    raise self.last_attempt.result()
  File "/usr/local/lib/python3.7/concurrent/futures/_base.py", line 428, in result
    return self.__get_result()
  File "/usr/local/lib/python3.7/concurrent/futures/_base.py", line 384, in __get_result
    raise self._exception
  File "/home/airflow/.local/lib/python3.7/site-packages/airflow/providers/ssh/hooks/ssh.py", line 335, in get_conn
    client.connect(**connect_kwargs)
  File "/home/airflow/.local/lib/python3.7/site-packages/paramiko/client.py", line 358, in connect
    retry_on_signal(lambda: sock.connect(addr))
  File "/home/airflow/.local/lib/python3.7/site-packages/paramiko/util.py", line 279, in retry_on_signal
    return function()
  File "/home/airflow/.local/lib/python3.7/site-packages/paramiko/client.py", line 358, in <lambda>
    retry_on_signal(lambda: sock.connect(addr))
socket.timeout: timed out
[2023-01-30T17:17:58.759+0000] {taskinstance.py:1323} INFO - Marking task as UP_FOR_RETRY. dag_id=crawl_data, task_id=save-to-hdfs, execution_date=20230130T160500, start_date=20230130T171720, end_date=20230130T171758
[2023-01-30T17:17:58.772+0000] {standard_task_runner.py:105} ERROR - Failed to execute job 1939 for task save-to-hdfs (timed out; 16756)
[2023-01-30T17:17:58.786+0000] {local_task_job.py:208} INFO - Task exited with return code 1
[2023-01-30T17:17:58.802+0000] {taskinstance.py:2578} INFO - 0 downstream tasks scheduled from follow-on schedule check
