[2023-01-29T15:25:47.137+0000] {taskinstance.py:1083} INFO - Dependencies all met for <TaskInstance: crawl_tienphong.save-to-hdfs manual__2023-01-29T15:25:26.014526+00:00 [queued]>
[2023-01-29T15:25:47.146+0000] {taskinstance.py:1083} INFO - Dependencies all met for <TaskInstance: crawl_tienphong.save-to-hdfs manual__2023-01-29T15:25:26.014526+00:00 [queued]>
[2023-01-29T15:25:47.146+0000] {taskinstance.py:1279} INFO - 
--------------------------------------------------------------------------------
[2023-01-29T15:25:47.146+0000] {taskinstance.py:1280} INFO - Starting attempt 1 of 4
[2023-01-29T15:25:47.146+0000] {taskinstance.py:1281} INFO - 
--------------------------------------------------------------------------------
[2023-01-29T15:25:47.163+0000] {taskinstance.py:1300} INFO - Executing <Task(SSHOperator): save-to-hdfs> on 2023-01-29 15:25:26.014526+00:00
[2023-01-29T15:25:47.167+0000] {standard_task_runner.py:55} INFO - Started process 10917 to run task
[2023-01-29T15:25:47.169+0000] {standard_task_runner.py:82} INFO - Running: ['***', 'tasks', 'run', 'crawl_tienphong', 'save-to-hdfs', 'manual__2023-01-29T15:25:26.014526+00:00', '--job-id', '1404', '--raw', '--subdir', 'DAGS_FOLDER/crawl_tienphong.py', '--cfg-path', '/tmp/tmp0s4b_b74']
[2023-01-29T15:25:47.170+0000] {standard_task_runner.py:83} INFO - Job 1404: Subtask save-to-hdfs
[2023-01-29T15:25:47.219+0000] {task_command.py:388} INFO - Running <TaskInstance: crawl_tienphong.save-to-hdfs manual__2023-01-29T15:25:26.014526+00:00 [running]> on host 9be4ecca8506
[2023-01-29T15:25:47.283+0000] {taskinstance.py:1509} INFO - Exporting the following env vars:
AIRFLOW_CTX_DAG_OWNER=phukaioh
AIRFLOW_CTX_DAG_ID=crawl_tienphong
AIRFLOW_CTX_TASK_ID=save-to-hdfs
AIRFLOW_CTX_EXECUTION_DATE=2023-01-29T15:25:26.014526+00:00
AIRFLOW_CTX_TRY_NUMBER=1
AIRFLOW_CTX_DAG_RUN_ID=manual__2023-01-29T15:25:26.014526+00:00
[2023-01-29T15:25:47.283+0000] {ssh.py:133} INFO - Creating ssh_client
[2023-01-29T15:25:47.283+0000] {ssh.py:111} INFO - ssh_hook is not provided or invalid. Trying ssh_conn_id to create SSHHook.
[2023-01-29T15:25:47.284+0000] {connection.py:432} ERROR - Unable to retrieve connection from secrets backend (EnvironmentVariablesBackend). Checking subsequent secrets backend.
Traceback (most recent call last):
  File "/home/airflow/.local/lib/python3.7/site-packages/airflow/models/connection.py", line 425, in get_connection_from_secrets
    conn = secrets_backend.get_connection(conn_id=conn_id)
  File "/home/airflow/.local/lib/python3.7/site-packages/airflow/secrets/base_secrets.py", line 95, in get_connection
    value = self.get_conn_value(conn_id=conn_id)
  File "/home/airflow/.local/lib/python3.7/site-packages/airflow/secrets/environment_variables.py", line 49, in get_conn_value
    return os.environ.get(CONN_ENV_PREFIX + conn_id.upper())
AttributeError: 'SSHHook' object has no attribute 'upper'
[2023-01-29T15:25:47.290+0000] {connection.py:432} ERROR - Unable to retrieve connection from secrets backend (MetastoreBackend). Checking subsequent secrets backend.
Traceback (most recent call last):
  File "/home/airflow/.local/lib/python3.7/site-packages/sqlalchemy/engine/base.py", line 1901, in _execute_context
    cursor, statement, parameters, context
  File "/home/airflow/.local/lib/python3.7/site-packages/sqlalchemy/engine/default.py", line 736, in do_execute
    cursor.execute(statement, parameters)
psycopg2.ProgrammingError: can't adapt type 'SSHHook'

The above exception was the direct cause of the following exception:

Traceback (most recent call last):
  File "/home/airflow/.local/lib/python3.7/site-packages/airflow/models/connection.py", line 425, in get_connection_from_secrets
    conn = secrets_backend.get_connection(conn_id=conn_id)
  File "/home/airflow/.local/lib/python3.7/site-packages/airflow/utils/session.py", line 75, in wrapper
    return func(*args, session=session, **kwargs)
  File "/home/airflow/.local/lib/python3.7/site-packages/airflow/secrets/metastore.py", line 39, in get_connection
    conn = session.query(Connection).filter(Connection.conn_id == conn_id).first()
  File "/home/airflow/.local/lib/python3.7/site-packages/sqlalchemy/orm/query.py", line 2824, in first
    return self.limit(1)._iter().first()
  File "/home/airflow/.local/lib/python3.7/site-packages/sqlalchemy/orm/query.py", line 2919, in _iter
    execution_options={"_sa_orm_load_options": self.load_options},
  File "/home/airflow/.local/lib/python3.7/site-packages/sqlalchemy/orm/session.py", line 1714, in execute
    result = conn._execute_20(statement, params or {}, execution_options)
  File "/home/airflow/.local/lib/python3.7/site-packages/sqlalchemy/engine/base.py", line 1705, in _execute_20
    return meth(self, args_10style, kwargs_10style, execution_options)
  File "/home/airflow/.local/lib/python3.7/site-packages/sqlalchemy/sql/elements.py", line 335, in _execute_on_connection
    self, multiparams, params, execution_options
  File "/home/airflow/.local/lib/python3.7/site-packages/sqlalchemy/engine/base.py", line 1582, in _execute_clauseelement
    cache_hit=cache_hit,
  File "/home/airflow/.local/lib/python3.7/site-packages/sqlalchemy/engine/base.py", line 1944, in _execute_context
    e, statement, parameters, cursor, context
  File "/home/airflow/.local/lib/python3.7/site-packages/sqlalchemy/engine/base.py", line 2125, in _handle_dbapi_exception
    sqlalchemy_exception, with_traceback=exc_info[2], from_=e
  File "/home/airflow/.local/lib/python3.7/site-packages/sqlalchemy/util/compat.py", line 211, in raise_
    raise exception
  File "/home/airflow/.local/lib/python3.7/site-packages/sqlalchemy/engine/base.py", line 1901, in _execute_context
    cursor, statement, parameters, context
  File "/home/airflow/.local/lib/python3.7/site-packages/sqlalchemy/engine/default.py", line 736, in do_execute
    cursor.execute(statement, parameters)
sqlalchemy.exc.ProgrammingError: (psycopg2.ProgrammingError) can't adapt type 'SSHHook'
[SQL: SELECT connection.password AS connection_password, connection.extra AS connection_extra, connection.id AS connection_id, connection.conn_id AS connection_conn_id, connection.conn_type AS connection_conn_type, connection.description AS connection_description, connection.host AS connection_host, connection.schema AS connection_schema, connection.login AS connection_login, connection.port AS connection_port, connection.is_encrypted AS connection_is_encrypted, connection.is_extra_encrypted AS connection_is_extra_encrypted 
FROM connection 
WHERE connection.conn_id = %(conn_id_1)s 
 LIMIT %(param_1)s]
[parameters: {'conn_id_1': <airflow.providers.ssh.hooks.ssh.SSHHook object at 0x7fef87ceac10>, 'param_1': 1}]
(Background on this error at: https://sqlalche.me/e/14/f405)
[2023-01-29T15:25:47.311+0000] {taskinstance.py:1768} ERROR - Task failed with exception
Traceback (most recent call last):
  File "/home/airflow/.local/lib/python3.7/site-packages/airflow/providers/ssh/operators/ssh.py", line 170, in execute
    with self.get_ssh_client() as ssh_client:
  File "/home/airflow/.local/lib/python3.7/site-packages/airflow/providers/ssh/operators/ssh.py", line 134, in get_ssh_client
    return self.get_hook().get_conn()
  File "/home/airflow/.local/lib/python3.7/site-packages/airflow/providers/ssh/operators/ssh.py", line 115, in get_hook
    banner_timeout=self.banner_timeout,
  File "/home/airflow/.local/lib/python3.7/site-packages/airflow/providers/ssh/hooks/ssh.py", line 143, in __init__
    conn = self.get_connection(self.ssh_conn_id)
  File "/home/airflow/.local/lib/python3.7/site-packages/airflow/hooks/base.py", line 72, in get_connection
    conn = Connection.get_connection_from_secrets(conn_id)
  File "/home/airflow/.local/lib/python3.7/site-packages/airflow/models/connection.py", line 435, in get_connection_from_secrets
    raise AirflowNotFoundException(f"The conn_id `{conn_id}` isn't defined")
airflow.exceptions.AirflowNotFoundException: The conn_id `<***.providers.ssh.hooks.ssh.SSHHook object at 0x7fef87ceac10>` isn't defined
[2023-01-29T15:25:47.314+0000] {taskinstance.py:1323} INFO - Marking task as UP_FOR_RETRY. dag_id=crawl_tienphong, task_id=save-to-hdfs, execution_date=20230129T152526, start_date=20230129T152547, end_date=20230129T152547
[2023-01-29T15:25:47.324+0000] {standard_task_runner.py:105} ERROR - Failed to execute job 1404 for task save-to-hdfs (The conn_id `<***.providers.ssh.hooks.ssh.SSHHook object at 0x7fef87ceac10>` isn't defined; 10917)
[2023-01-29T15:25:47.341+0000] {local_task_job.py:208} INFO - Task exited with return code 1
[2023-01-29T15:25:47.357+0000] {taskinstance.py:2578} INFO - 0 downstream tasks scheduled from follow-on schedule check
