[2023-01-29T15:24:04.544+0000] {taskinstance.py:1083} INFO - Dependencies all met for <TaskInstance: crawl_tienphong.save-to-hdfs manual__2023-01-29T15:18:40.270269+00:00 [queued]>
[2023-01-29T15:24:04.554+0000] {taskinstance.py:1083} INFO - Dependencies all met for <TaskInstance: crawl_tienphong.save-to-hdfs manual__2023-01-29T15:18:40.270269+00:00 [queued]>
[2023-01-29T15:24:04.554+0000] {taskinstance.py:1279} INFO - 
--------------------------------------------------------------------------------
[2023-01-29T15:24:04.554+0000] {taskinstance.py:1280} INFO - Starting attempt 2 of 4
[2023-01-29T15:24:04.555+0000] {taskinstance.py:1281} INFO - 
--------------------------------------------------------------------------------
[2023-01-29T15:24:04.572+0000] {taskinstance.py:1300} INFO - Executing <Task(SSHOperator): save-to-hdfs> on 2023-01-29 15:18:40.270269+00:00
[2023-01-29T15:24:04.577+0000] {standard_task_runner.py:55} INFO - Started process 10756 to run task
[2023-01-29T15:24:04.580+0000] {standard_task_runner.py:82} INFO - Running: ['***', 'tasks', 'run', 'crawl_tienphong', 'save-to-hdfs', 'manual__2023-01-29T15:18:40.270269+00:00', '--job-id', '1401', '--raw', '--subdir', 'DAGS_FOLDER/crawl_tienphong.py', '--cfg-path', '/tmp/tmpw73d3jxj']
[2023-01-29T15:24:04.580+0000] {standard_task_runner.py:83} INFO - Job 1401: Subtask save-to-hdfs
[2023-01-29T15:24:04.645+0000] {task_command.py:388} INFO - Running <TaskInstance: crawl_tienphong.save-to-hdfs manual__2023-01-29T15:18:40.270269+00:00 [running]> on host 9be4ecca8506
[2023-01-29T15:24:04.735+0000] {taskinstance.py:1509} INFO - Exporting the following env vars:
AIRFLOW_CTX_DAG_OWNER=phukaioh
AIRFLOW_CTX_DAG_ID=crawl_tienphong
AIRFLOW_CTX_TASK_ID=save-to-hdfs
AIRFLOW_CTX_EXECUTION_DATE=2023-01-29T15:18:40.270269+00:00
AIRFLOW_CTX_TRY_NUMBER=2
AIRFLOW_CTX_DAG_RUN_ID=manual__2023-01-29T15:18:40.270269+00:00
[2023-01-29T15:24:04.735+0000] {ssh.py:133} INFO - Creating ssh_client
[2023-01-29T15:24:04.774+0000] {ssh.py:111} INFO - ssh_hook is not provided or invalid. Trying ssh_conn_id to create SSHHook.
[2023-01-29T15:24:04.795+0000] {taskinstance.py:1768} ERROR - Task failed with exception
Traceback (most recent call last):
  File "/home/airflow/.local/lib/python3.7/site-packages/airflow/providers/ssh/operators/ssh.py", line 170, in execute
    with self.get_ssh_client() as ssh_client:
  File "/home/airflow/.local/lib/python3.7/site-packages/airflow/providers/ssh/operators/ssh.py", line 134, in get_ssh_client
    return self.get_hook().get_conn()
  File "/home/airflow/.local/lib/python3.7/site-packages/airflow/providers/ssh/operators/ssh.py", line 115, in get_hook
    banner_timeout=self.banner_timeout,
  File "/home/airflow/.local/lib/python3.7/site-packages/airflow/providers/ssh/hooks/ssh.py", line 143, in __init__
    conn = self.get_connection(self.ssh_conn_id)
  File "/home/airflow/.local/lib/python3.7/site-packages/airflow/hooks/base.py", line 72, in get_connection
    conn = Connection.get_connection_from_secrets(conn_id)
  File "/home/airflow/.local/lib/python3.7/site-packages/airflow/models/connection.py", line 435, in get_connection_from_secrets
    raise AirflowNotFoundException(f"The conn_id `{conn_id}` isn't defined")
airflow.exceptions.AirflowNotFoundException: The conn_id `ssh phukaioh@192.168.19.179` isn't defined
[2023-01-29T15:24:04.801+0000] {taskinstance.py:1323} INFO - Marking task as UP_FOR_RETRY. dag_id=crawl_tienphong, task_id=save-to-hdfs, execution_date=20230129T151840, start_date=20230129T152404, end_date=20230129T152404
[2023-01-29T15:24:04.819+0000] {standard_task_runner.py:105} ERROR - Failed to execute job 1401 for task save-to-hdfs (The conn_id `ssh phukaioh@192.168.19.179` isn't defined; 10756)
[2023-01-29T15:24:04.832+0000] {local_task_job.py:208} INFO - Task exited with return code 1
[2023-01-29T15:24:04.856+0000] {taskinstance.py:2578} INFO - 0 downstream tasks scheduled from follow-on schedule check
