[2023-01-27T14:41:15.893+0000] {taskinstance.py:1083} INFO - Dependencies all met for <TaskInstance: crawl_tienphong.crawler manual__2023-01-27T14:41:13.459442+00:00 [queued]>
[2023-01-27T14:41:15.906+0000] {taskinstance.py:1083} INFO - Dependencies all met for <TaskInstance: crawl_tienphong.crawler manual__2023-01-27T14:41:13.459442+00:00 [queued]>
[2023-01-27T14:41:15.906+0000] {taskinstance.py:1279} INFO - 
--------------------------------------------------------------------------------
[2023-01-27T14:41:15.906+0000] {taskinstance.py:1280} INFO - Starting attempt 1 of 4
[2023-01-27T14:41:15.906+0000] {taskinstance.py:1281} INFO - 
--------------------------------------------------------------------------------
[2023-01-27T14:41:15.931+0000] {taskinstance.py:1300} INFO - Executing <Task(BashOperator): crawler> on 2023-01-27 14:41:13.459442+00:00
[2023-01-27T14:41:15.937+0000] {standard_task_runner.py:55} INFO - Started process 3724 to run task
[2023-01-27T14:41:15.940+0000] {standard_task_runner.py:82} INFO - Running: ['***', 'tasks', 'run', 'crawl_tienphong', 'crawler', 'manual__2023-01-27T14:41:13.459442+00:00', '--job-id', '419', '--raw', '--subdir', 'DAGS_FOLDER/crawl_tienphong.py', '--cfg-path', '/tmp/tmp378gzafk']
[2023-01-27T14:41:15.940+0000] {standard_task_runner.py:83} INFO - Job 419: Subtask crawler
[2023-01-27T14:41:16.023+0000] {task_command.py:388} INFO - Running <TaskInstance: crawl_tienphong.crawler manual__2023-01-27T14:41:13.459442+00:00 [running]> on host 9be4ecca8506
[2023-01-27T14:41:16.131+0000] {taskinstance.py:1509} INFO - Exporting the following env vars:
AIRFLOW_CTX_DAG_OWNER=phukaioh
AIRFLOW_CTX_DAG_ID=crawl_tienphong
AIRFLOW_CTX_TASK_ID=crawler
AIRFLOW_CTX_EXECUTION_DATE=2023-01-27T14:41:13.459442+00:00
AIRFLOW_CTX_TRY_NUMBER=1
AIRFLOW_CTX_DAG_RUN_ID=manual__2023-01-27T14:41:13.459442+00:00
[2023-01-27T14:41:16.132+0000] {subprocess.py:63} INFO - Tmp dir root location: 
 /tmp
[2023-01-27T14:41:16.133+0000] {subprocess.py:75} INFO - Running command: ['/bin/bash', '-c', 'cd /opt/project/ && ls -la && pip install scrapy && scrapy version ']
[2023-01-27T14:41:16.146+0000] {subprocess.py:86} INFO - Output:
[2023-01-27T14:41:16.150+0000] {subprocess.py:93} INFO - total 36
[2023-01-27T14:41:16.150+0000] {subprocess.py:93} INFO - drwxrwxr-x 5 default 1001 4096 Jan 27 14:40 .
[2023-01-27T14:41:16.150+0000] {subprocess.py:93} INFO - drwxr-xr-x 1 root    root 4096 Jan 27 13:53 ..
[2023-01-27T14:41:16.150+0000] {subprocess.py:93} INFO - drwxrwxr-x 4 default 1001 4096 Jan 26 03:12 crawler
[2023-01-27T14:41:16.150+0000] {subprocess.py:93} INFO - drwxrwxr-x 2 default 1001 4096 Jan 27 13:29 data
[2023-01-27T14:41:16.150+0000] {subprocess.py:93} INFO - -rw-rw-r-- 1 default 1001   69 Jan 27 13:13 run_crawl_tienphong.sh
[2023-01-27T14:41:16.151+0000] {subprocess.py:93} INFO - -rw-rw-r-- 1 default 1001  257 Jan 26 03:08 scrapy.cfg
[2023-01-27T14:41:16.151+0000] {subprocess.py:93} INFO - drwxrwxr-x 2 default 1001 4096 Jan 27 13:29 source
[2023-01-27T14:41:16.151+0000] {subprocess.py:93} INFO - -rw-rw-r-- 1 default 1001    6 Jan 27 13:16 test.sh
[2023-01-27T14:41:18.376+0000] {subprocess.py:93} INFO - Defaulting to user installation because normal site-packages is not writeable
[2023-01-27T14:41:19.822+0000] {subprocess.py:93} INFO - Collecting scrapy
[2023-01-27T14:41:34.856+0000] {subprocess.py:93} INFO -   WARNING: Retrying (Retry(total=4, connect=None, read=None, redirect=None, status=None)) after connection broken by 'ConnectTimeoutError(<pip._vendor.urllib3.connection.HTTPSConnection object at 0x7f9ed35a97d0>, 'Connection to files.pythonhosted.org timed out. (connect timeout=15)')': /packages/00/34/9598461dfc319a2cda4c7eb8322f7f5c88979e9fc2a29385cec677b93af1/Scrapy-2.7.1-py2.py3-none-any.whl
[2023-01-27T14:41:36.419+0000] {subprocess.py:93} INFO -   Downloading Scrapy-2.7.1-py2.py3-none-any.whl (271 kB)
[2023-01-27T14:42:10.692+0000] {subprocess.py:93} INFO -      ━━━━━━━━━━━━━━━━━━━━━━━━━━━━━━━━━━━━━━━ 271.5/271.5 kB 5.2 kB/s eta 0:00:00
[2023-01-27T14:42:10.724+0000] {subprocess.py:93} INFO - Requirement already satisfied: packaging in /home/***/.local/lib/python3.7/site-packages (from scrapy) (21.3)
[2023-01-27T14:42:11.212+0000] {subprocess.py:93} INFO - Collecting itemadapter>=0.1.0
[2023-01-27T14:42:11.317+0000] {subprocess.py:93} INFO -   Downloading itemadapter-0.7.0-py3-none-any.whl (10 kB)
[2023-01-27T14:42:12.503+0000] {subprocess.py:93} INFO - Collecting w3lib>=1.17.0
[2023-01-27T14:42:12.610+0000] {subprocess.py:93} INFO -   Downloading w3lib-2.1.1-py3-none-any.whl (21 kB)
[2023-01-27T14:42:14.445+0000] {subprocess.py:93} INFO - Requirement already satisfied: lxml>=4.3.0 in /home/***/.local/lib/python3.7/site-packages (from scrapy) (4.9.2)
[2023-01-27T14:42:14.580+0000] {subprocess.py:93} INFO - Collecting PyDispatcher>=2.0.5
[2023-01-27T14:42:15.482+0000] {subprocess.py:93} INFO -   Downloading PyDispatcher-2.0.6.tar.gz (38 kB)
[2023-01-27T14:42:20.080+0000] {subprocess.py:93} INFO -   Preparing metadata (setup.py): started
[2023-01-27T14:42:21.427+0000] {subprocess.py:93} INFO -   Preparing metadata (setup.py): finished with status 'done'
[2023-01-27T14:42:21.434+0000] {subprocess.py:93} INFO - Requirement already satisfied: zope.interface>=5.1.0 in /home/***/.local/lib/python3.7/site-packages (from scrapy) (5.5.2)
[2023-01-27T14:42:21.434+0000] {subprocess.py:93} INFO - Requirement already satisfied: cryptography>=3.3 in /home/***/.local/lib/python3.7/site-packages (from scrapy) (38.0.4)
[2023-01-27T14:42:21.812+0000] {subprocess.py:93} INFO - Collecting tldextract
[2023-01-27T14:42:21.921+0000] {subprocess.py:93} INFO -   Downloading tldextract-3.4.0-py3-none-any.whl (93 kB)
[2023-01-27T14:42:29.991+0000] {subprocess.py:93} INFO -      ━━━━━━━━━━━━━━━━━━━━━━━━━━━━━━━━━━━━━━━━ 93.9/93.9 kB 12.1 kB/s eta 0:00:00
[2023-01-27T14:42:30.505+0000] {subprocess.py:93} INFO - Collecting protego>=0.1.15
[2023-01-27T14:42:30.610+0000] {subprocess.py:93} INFO -   Downloading Protego-0.2.1-py2.py3-none-any.whl (8.2 kB)
[2023-01-27T14:42:31.741+0000] {subprocess.py:93} INFO - Collecting cssselect>=0.9.1
[2023-01-27T14:42:31.841+0000] {subprocess.py:93} INFO -   Downloading cssselect-1.2.0-py2.py3-none-any.whl (18 kB)
[2023-01-27T14:42:36.213+0000] {subprocess.py:93} INFO - Collecting Twisted>=18.9.0
[2023-01-27T14:42:36.465+0000] {subprocess.py:93} INFO -   Downloading Twisted-22.10.0-py3-none-any.whl (3.1 MB)
[2023-01-27T14:45:15.335+0000] {subprocess.py:93} INFO -      ━━━━━━━━━━━━━                            1.0/3.1 MB 8.4 kB/s eta 0:04:06
[2023-01-27T14:45:15.341+0000] {subprocess.py:93} INFO - ERROR: Exception:
[2023-01-27T14:45:15.341+0000] {subprocess.py:93} INFO - Traceback (most recent call last):
[2023-01-27T14:45:15.341+0000] {subprocess.py:93} INFO -   File "/home/***/.local/lib/python3.7/site-packages/pip/_vendor/urllib3/response.py", line 437, in _error_catcher
[2023-01-27T14:45:15.341+0000] {subprocess.py:93} INFO -     yield
[2023-01-27T14:45:15.341+0000] {subprocess.py:93} INFO -   File "/home/***/.local/lib/python3.7/site-packages/pip/_vendor/urllib3/response.py", line 560, in read
[2023-01-27T14:45:15.342+0000] {subprocess.py:93} INFO -     data = self._fp_read(amt) if not fp_closed else b""
[2023-01-27T14:45:15.342+0000] {subprocess.py:93} INFO -   File "/home/***/.local/lib/python3.7/site-packages/pip/_vendor/urllib3/response.py", line 526, in _fp_read
[2023-01-27T14:45:15.342+0000] {subprocess.py:93} INFO -     return self._fp.read(amt) if amt is not None else self._fp.read()
[2023-01-27T14:45:15.342+0000] {subprocess.py:93} INFO -   File "/home/***/.local/lib/python3.7/site-packages/pip/_vendor/cachecontrol/filewrapper.py", line 90, in read
[2023-01-27T14:45:15.342+0000] {subprocess.py:93} INFO -     data = self.__fp.read(amt)
[2023-01-27T14:45:15.342+0000] {subprocess.py:93} INFO -   File "/usr/local/lib/python3.7/http/client.py", line 465, in read
[2023-01-27T14:45:15.342+0000] {subprocess.py:93} INFO -     n = self.readinto(b)
[2023-01-27T14:45:15.343+0000] {subprocess.py:93} INFO -   File "/usr/local/lib/python3.7/http/client.py", line 509, in readinto
[2023-01-27T14:45:15.343+0000] {subprocess.py:93} INFO -     n = self.fp.readinto(b)
[2023-01-27T14:45:15.343+0000] {subprocess.py:93} INFO -   File "/usr/local/lib/python3.7/socket.py", line 589, in readinto
[2023-01-27T14:45:15.343+0000] {subprocess.py:93} INFO -     return self._sock.recv_into(b)
[2023-01-27T14:45:15.343+0000] {subprocess.py:93} INFO -   File "/usr/local/lib/python3.7/ssl.py", line 1071, in recv_into
[2023-01-27T14:45:15.343+0000] {subprocess.py:93} INFO -     return self.read(nbytes, buffer)
[2023-01-27T14:45:15.343+0000] {subprocess.py:93} INFO -   File "/usr/local/lib/python3.7/ssl.py", line 929, in read
[2023-01-27T14:45:15.344+0000] {subprocess.py:93} INFO -     return self._sslobj.read(len, buffer)
[2023-01-27T14:45:15.344+0000] {subprocess.py:93} INFO - socket.timeout: The read operation timed out
[2023-01-27T14:45:15.344+0000] {subprocess.py:93} INFO - 
[2023-01-27T14:45:15.344+0000] {subprocess.py:93} INFO - During handling of the above exception, another exception occurred:
[2023-01-27T14:45:15.344+0000] {subprocess.py:93} INFO - 
[2023-01-27T14:45:15.344+0000] {subprocess.py:93} INFO - Traceback (most recent call last):
[2023-01-27T14:45:15.344+0000] {subprocess.py:93} INFO -   File "/home/***/.local/lib/python3.7/site-packages/pip/_internal/cli/base_command.py", line 160, in exc_logging_wrapper
[2023-01-27T14:45:15.344+0000] {subprocess.py:93} INFO -     status = run_func(*args)
[2023-01-27T14:45:15.345+0000] {subprocess.py:93} INFO -   File "/home/***/.local/lib/python3.7/site-packages/pip/_internal/cli/req_command.py", line 247, in wrapper
[2023-01-27T14:45:15.345+0000] {subprocess.py:93} INFO -     return func(self, options, args)
[2023-01-27T14:45:15.345+0000] {subprocess.py:93} INFO -   File "/home/***/.local/lib/python3.7/site-packages/pip/_internal/commands/install.py", line 401, in run
[2023-01-27T14:45:15.345+0000] {subprocess.py:93} INFO -     reqs, check_supported_wheels=not options.target_dir
[2023-01-27T14:45:15.345+0000] {subprocess.py:93} INFO -   File "/home/***/.local/lib/python3.7/site-packages/pip/_internal/resolution/resolvelib/resolver.py", line 93, in resolve
[2023-01-27T14:45:15.345+0000] {subprocess.py:93} INFO -     collected.requirements, max_rounds=try_to_avoid_resolution_too_deep
[2023-01-27T14:45:15.345+0000] {subprocess.py:93} INFO -   File "/home/***/.local/lib/python3.7/site-packages/pip/_vendor/resolvelib/resolvers.py", line 481, in resolve
[2023-01-27T14:45:15.346+0000] {subprocess.py:93} INFO -     state = resolution.resolve(requirements, max_rounds=max_rounds)
[2023-01-27T14:45:15.346+0000] {subprocess.py:93} INFO -   File "/home/***/.local/lib/python3.7/site-packages/pip/_vendor/resolvelib/resolvers.py", line 373, in resolve
[2023-01-27T14:45:15.346+0000] {subprocess.py:93} INFO -     failure_causes = self._attempt_to_pin_criterion(name)
[2023-01-27T14:45:15.346+0000] {subprocess.py:93} INFO -   File "/home/***/.local/lib/python3.7/site-packages/pip/_vendor/resolvelib/resolvers.py", line 213, in _attempt_to_pin_criterion
[2023-01-27T14:45:15.346+0000] {subprocess.py:93} INFO -     criteria = self._get_updated_criteria(candidate)
[2023-01-27T14:45:15.346+0000] {subprocess.py:93} INFO -   File "/home/***/.local/lib/python3.7/site-packages/pip/_vendor/resolvelib/resolvers.py", line 204, in _get_updated_criteria
[2023-01-27T14:45:15.346+0000] {subprocess.py:93} INFO -     self._add_to_criteria(criteria, requirement, parent=candidate)
[2023-01-27T14:45:15.346+0000] {subprocess.py:93} INFO -   File "/home/***/.local/lib/python3.7/site-packages/pip/_vendor/resolvelib/resolvers.py", line 172, in _add_to_criteria
[2023-01-27T14:45:15.347+0000] {subprocess.py:93} INFO -     if not criterion.candidates:
[2023-01-27T14:45:15.347+0000] {subprocess.py:93} INFO -   File "/home/***/.local/lib/python3.7/site-packages/pip/_vendor/resolvelib/structs.py", line 151, in __bool__
[2023-01-27T14:45:15.347+0000] {subprocess.py:93} INFO -     return bool(self._sequence)
[2023-01-27T14:45:15.347+0000] {subprocess.py:93} INFO -   File "/home/***/.local/lib/python3.7/site-packages/pip/_internal/resolution/resolvelib/found_candidates.py", line 155, in __bool__
[2023-01-27T14:45:15.347+0000] {subprocess.py:93} INFO -     return any(self)
[2023-01-27T14:45:15.347+0000] {subprocess.py:93} INFO -   File "/home/***/.local/lib/python3.7/site-packages/pip/_internal/resolution/resolvelib/found_candidates.py", line 143, in <genexpr>
[2023-01-27T14:45:15.347+0000] {subprocess.py:93} INFO -     return (c for c in iterator if id(c) not in self._incompatible_ids)
[2023-01-27T14:45:15.347+0000] {subprocess.py:93} INFO -   File "/home/***/.local/lib/python3.7/site-packages/pip/_internal/resolution/resolvelib/found_candidates.py", line 47, in _iter_built
[2023-01-27T14:45:15.348+0000] {subprocess.py:93} INFO -     candidate = func()
[2023-01-27T14:45:15.348+0000] {subprocess.py:93} INFO -   File "/home/***/.local/lib/python3.7/site-packages/pip/_internal/resolution/resolvelib/factory.py", line 211, in _make_candidate_from_link
[2023-01-27T14:45:15.348+0000] {subprocess.py:93} INFO -     version=version,
[2023-01-27T14:45:15.348+0000] {subprocess.py:93} INFO -   File "/home/***/.local/lib/python3.7/site-packages/pip/_internal/resolution/resolvelib/candidates.py", line 303, in __init__
[2023-01-27T14:45:15.348+0000] {subprocess.py:93} INFO -     version=version,
[2023-01-27T14:45:15.348+0000] {subprocess.py:93} INFO -   File "/home/***/.local/lib/python3.7/site-packages/pip/_internal/resolution/resolvelib/candidates.py", line 162, in __init__
[2023-01-27T14:45:15.348+0000] {subprocess.py:93} INFO -     self.dist = self._prepare()
[2023-01-27T14:45:15.348+0000] {subprocess.py:93} INFO -   File "/home/***/.local/lib/python3.7/site-packages/pip/_internal/resolution/resolvelib/candidates.py", line 231, in _prepare
[2023-01-27T14:45:15.348+0000] {subprocess.py:93} INFO -     dist = self._prepare_distribution()
[2023-01-27T14:45:15.348+0000] {subprocess.py:93} INFO -   File "/home/***/.local/lib/python3.7/site-packages/pip/_internal/resolution/resolvelib/candidates.py", line 308, in _prepare_distribution
[2023-01-27T14:45:15.348+0000] {subprocess.py:93} INFO -     return preparer.prepare_linked_requirement(self._ireq, parallel_builds=True)
[2023-01-27T14:45:15.349+0000] {subprocess.py:93} INFO -   File "/home/***/.local/lib/python3.7/site-packages/pip/_internal/operations/prepare.py", line 491, in prepare_linked_requirement
[2023-01-27T14:45:15.349+0000] {subprocess.py:93} INFO -     return self._prepare_linked_requirement(req, parallel_builds)
[2023-01-27T14:45:15.349+0000] {subprocess.py:93} INFO -   File "/home/***/.local/lib/python3.7/site-packages/pip/_internal/operations/prepare.py", line 542, in _prepare_linked_requirement
[2023-01-27T14:45:15.349+0000] {subprocess.py:93} INFO -     hashes,
[2023-01-27T14:45:15.349+0000] {subprocess.py:93} INFO -   File "/home/***/.local/lib/python3.7/site-packages/pip/_internal/operations/prepare.py", line 170, in unpack_url
[2023-01-27T14:45:15.349+0000] {subprocess.py:93} INFO -     hashes=hashes,
[2023-01-27T14:45:15.349+0000] {subprocess.py:93} INFO -   File "/home/***/.local/lib/python3.7/site-packages/pip/_internal/operations/prepare.py", line 107, in get_http_url
[2023-01-27T14:45:15.350+0000] {subprocess.py:93} INFO -     from_path, content_type = download(link, temp_dir.path)
[2023-01-27T14:45:15.350+0000] {subprocess.py:93} INFO -   File "/home/***/.local/lib/python3.7/site-packages/pip/_internal/network/download.py", line 147, in __call__
[2023-01-27T14:45:15.350+0000] {subprocess.py:93} INFO -     for chunk in chunks:
[2023-01-27T14:45:15.350+0000] {subprocess.py:93} INFO -   File "/home/***/.local/lib/python3.7/site-packages/pip/_internal/cli/progress_bars.py", line 53, in _rich_progress_bar
[2023-01-27T14:45:15.350+0000] {subprocess.py:93} INFO -     for chunk in iterable:
[2023-01-27T14:45:15.350+0000] {subprocess.py:93} INFO -   File "/home/***/.local/lib/python3.7/site-packages/pip/_internal/network/utils.py", line 87, in response_chunks
[2023-01-27T14:45:15.351+0000] {subprocess.py:93} INFO -     decode_content=False,
[2023-01-27T14:45:15.351+0000] {subprocess.py:93} INFO -   File "/home/***/.local/lib/python3.7/site-packages/pip/_vendor/urllib3/response.py", line 621, in stream
[2023-01-27T14:45:15.351+0000] {subprocess.py:93} INFO -     data = self.read(amt=amt, decode_content=decode_content)
[2023-01-27T14:45:15.351+0000] {subprocess.py:93} INFO -   File "/home/***/.local/lib/python3.7/site-packages/pip/_vendor/urllib3/response.py", line 586, in read
[2023-01-27T14:45:15.351+0000] {subprocess.py:93} INFO -     raise IncompleteRead(self._fp_bytes_read, self.length_remaining)
[2023-01-27T14:45:15.351+0000] {subprocess.py:93} INFO -   File "/usr/local/lib/python3.7/contextlib.py", line 130, in __exit__
[2023-01-27T14:45:15.351+0000] {subprocess.py:93} INFO -     self.gen.throw(type, value, traceback)
[2023-01-27T14:45:15.352+0000] {subprocess.py:93} INFO -   File "/home/***/.local/lib/python3.7/site-packages/pip/_vendor/urllib3/response.py", line 442, in _error_catcher
[2023-01-27T14:45:15.352+0000] {subprocess.py:93} INFO -     raise ReadTimeoutError(self._pool, None, "Read timed out.")
[2023-01-27T14:45:15.352+0000] {subprocess.py:93} INFO - pip._vendor.urllib3.exceptions.ReadTimeoutError: HTTPSConnectionPool(host='files.pythonhosted.org', port=443): Read timed out.
[2023-01-27T14:45:15.460+0000] {subprocess.py:97} INFO - Command exited with return code 2
[2023-01-27T14:45:15.475+0000] {taskinstance.py:1768} ERROR - Task failed with exception
Traceback (most recent call last):
  File "/home/airflow/.local/lib/python3.7/site-packages/airflow/operators/bash.py", line 197, in execute
    f"Bash command failed. The command returned a non-zero exit code {result.exit_code}."
airflow.exceptions.AirflowException: Bash command failed. The command returned a non-zero exit code 2.
[2023-01-27T14:45:15.480+0000] {taskinstance.py:1323} INFO - Marking task as UP_FOR_RETRY. dag_id=crawl_tienphong, task_id=crawler, execution_date=20230127T144113, start_date=20230127T144115, end_date=20230127T144515
[2023-01-27T14:45:15.501+0000] {standard_task_runner.py:105} ERROR - Failed to execute job 419 for task crawler (Bash command failed. The command returned a non-zero exit code 2.; 3724)
[2023-01-27T14:45:15.523+0000] {local_task_job.py:208} INFO - Task exited with return code 1
[2023-01-27T14:45:15.543+0000] {taskinstance.py:2578} INFO - 0 downstream tasks scheduled from follow-on schedule check
