[2023-01-31T01:38:36.703+0000] {taskinstance.py:1083} INFO - Dependencies all met for <TaskInstance: crawl_data.save-to-hdfs scheduled__2023-01-30T17:05:00+00:00 [queued]>
[2023-01-31T01:38:36.712+0000] {taskinstance.py:1083} INFO - Dependencies all met for <TaskInstance: crawl_data.save-to-hdfs scheduled__2023-01-30T17:05:00+00:00 [queued]>
[2023-01-31T01:38:36.712+0000] {taskinstance.py:1279} INFO - 
--------------------------------------------------------------------------------
[2023-01-31T01:38:36.712+0000] {taskinstance.py:1280} INFO - Starting attempt 1 of 4
[2023-01-31T01:38:36.712+0000] {taskinstance.py:1281} INFO - 
--------------------------------------------------------------------------------
[2023-01-31T01:38:36.749+0000] {taskinstance.py:1300} INFO - Executing <Task(SSHOperator): save-to-hdfs> on 2023-01-30 17:05:00+00:00
[2023-01-31T01:38:36.757+0000] {standard_task_runner.py:55} INFO - Started process 119 to run task
[2023-01-31T01:38:36.762+0000] {standard_task_runner.py:82} INFO - Running: ['***', 'tasks', 'run', 'crawl_data', 'save-to-hdfs', 'scheduled__2023-01-30T17:05:00+00:00', '--job-id', '1966', '--raw', '--subdir', 'DAGS_FOLDER/crawl_data.py', '--cfg-path', '/tmp/tmpeok452t9']
[2023-01-31T01:38:36.763+0000] {standard_task_runner.py:83} INFO - Job 1966: Subtask save-to-hdfs
[2023-01-31T01:38:36.843+0000] {task_command.py:388} INFO - Running <TaskInstance: crawl_data.save-to-hdfs scheduled__2023-01-30T17:05:00+00:00 [running]> on host 9be4ecca8506
[2023-01-31T01:38:36.926+0000] {taskinstance.py:1509} INFO - Exporting the following env vars:
AIRFLOW_CTX_DAG_OWNER=phukaioh
AIRFLOW_CTX_DAG_ID=crawl_data
AIRFLOW_CTX_TASK_ID=save-to-hdfs
AIRFLOW_CTX_EXECUTION_DATE=2023-01-30T17:05:00+00:00
AIRFLOW_CTX_TRY_NUMBER=1
AIRFLOW_CTX_DAG_RUN_ID=scheduled__2023-01-30T17:05:00+00:00
[2023-01-31T01:38:36.927+0000] {ssh.py:133} INFO - Creating ssh_client
[2023-01-31T01:38:36.927+0000] {ssh.py:283} WARNING - No Host Key Verification. This won't protect against Man-In-The-Middle attacks
[2023-01-31T01:38:36.938+0000] {ssh.py:325} INFO - Failed to connect. Sleeping before retry attempt 1
[2023-01-31T01:38:40.822+0000] {ssh.py:325} INFO - Failed to connect. Sleeping before retry attempt 2
[2023-01-31T01:38:43.867+0000] {taskinstance.py:1768} ERROR - Task failed with exception
Traceback (most recent call last):
  File "/home/airflow/.local/lib/python3.7/site-packages/airflow/providers/ssh/operators/ssh.py", line 170, in execute
    with self.get_ssh_client() as ssh_client:
  File "/home/airflow/.local/lib/python3.7/site-packages/airflow/providers/ssh/operators/ssh.py", line 134, in get_ssh_client
    return self.get_hook().get_conn()
  File "/home/airflow/.local/lib/python3.7/site-packages/airflow/providers/ssh/hooks/ssh.py", line 332, in get_conn
    before_sleep=log_before_sleep,
  File "/home/airflow/.local/lib/python3.7/site-packages/tenacity/__init__.py", line 384, in __iter__
    do = self.iter(retry_state=retry_state)
  File "/home/airflow/.local/lib/python3.7/site-packages/tenacity/__init__.py", line 362, in iter
    raise retry_exc.reraise()
  File "/home/airflow/.local/lib/python3.7/site-packages/tenacity/__init__.py", line 195, in reraise
    raise self.last_attempt.result()
  File "/usr/local/lib/python3.7/concurrent/futures/_base.py", line 428, in result
    return self.__get_result()
  File "/usr/local/lib/python3.7/concurrent/futures/_base.py", line 384, in __get_result
    raise self._exception
  File "/home/airflow/.local/lib/python3.7/site-packages/airflow/providers/ssh/hooks/ssh.py", line 335, in get_conn
    client.connect(**connect_kwargs)
  File "/home/airflow/.local/lib/python3.7/site-packages/paramiko/client.py", line 381, in connect
    raise NoValidConnectionsError(errors)
paramiko.ssh_exception.NoValidConnectionsError: [Errno None] Unable to connect to port 22 on 192.168.141.42
[2023-01-31T01:38:43.916+0000] {taskinstance.py:1323} INFO - Marking task as UP_FOR_RETRY. dag_id=crawl_data, task_id=save-to-hdfs, execution_date=20230130T170500, start_date=20230131T013836, end_date=20230131T013843
[2023-01-31T01:38:43.954+0000] {standard_task_runner.py:105} ERROR - Failed to execute job 1966 for task save-to-hdfs ([Errno None] Unable to connect to port 22 on 192.168.141.42; 119)
[2023-01-31T01:38:43.973+0000] {local_task_job.py:208} INFO - Task exited with return code 1
[2023-01-31T01:38:43.993+0000] {taskinstance.py:2578} INFO - 0 downstream tasks scheduled from follow-on schedule check
